Workbook
Name CL: 'RELEVANCIA-PUNTAJE'!$B$2
Name L: 'RELEVANCIA-PUNTAJE'!$C$2
Name ML: 'RELEVANCIA-PUNTAJE'!$D$2
Name MR: 'RELEVANCIA-PUNTAJE'!$A$3
Name MR_CL: 'RELEVANCIA-PUNTAJE'!$B$3
Name MR_L: 'RELEVANCIA-PUNTAJE'!$C$3
Name MR_ML: 'RELEVANCIA-PUNTAJE'!$D$3
Name MR_NL: 'RELEVANCIA-PUNTAJE'!$E$3
Name MR_PL: 'RELEVANCIA-PUNTAJE'!#REF!
Name MR_TL: 'RELEVANCIA-PUNTAJE'!$B$3
Name NL: 'RELEVANCIA-PUNTAJE'!$E$2
Name PL: 'RELEVANCIA-PUNTAJE'!#REF!
Name PR: 'RELEVANCIA-PUNTAJE'!$A$5
Name PR_ML: 'RELEVANCIA-PUNTAJE'!$D$5
Name PR_NL: 'RELEVANCIA-PUNTAJE'!$E$5
Name PR_PL: 'RELEVANCIA-PUNTAJE'!#REF!
Name PR_TL: 'RELEVANCIA-PUNTAJE'!$B$5
Name RE: 'RELEVANCIA-PUNTAJE'!$A$4
Name RE_ML: 'RELEVANCIA-PUNTAJE'!$D$4
Name RE_NL: 'RELEVANCIA-PUNTAJE'!$E$4
Name RE_PL: 'RELEVANCIA-PUNTAJE'!#REF!
Name RE_TL: 'RELEVANCIA-PUNTAJE'!$B$4
Name TL: 'RELEVANCIA-PUNTAJE'!$B$2

Sheet EVALUACION1
C2: 0.75 | D2: 0.25 | E2: 1
B3: INTEGRANTES | C3: IEP o IEE: | D3: EMPLEAB
A4: 1 | B4: Carlos Manzo | C4: =EVALUACION1!$C$24 -> 6.3 | D4: =$C$35 -> 5.3 | E4: =C4*C$2+D4*D$2 -> 6.05
A5: 2 | B5: Benjamin Huentemilla | C5: =EVALUACION1!$C$24 -> 6.3 | D5: =C47 -> 5.3 | E5: =C5*C$2+D5*D$2 -> 6.05
A6: 3 | B6: Zuar Sepulveda | C6: =EVALUACION1!$C$24 -> 6.3 | D6: =C58 -> 5.3 | E6: =C6*C$2+D6*D$2 -> 6.05
A11: GRUPAL | C11: Nivel de Logro | D11: NIVELES DE LOGRO Y PUNTAJES
B12: Aspectos a Evaluar | D12: Completamente logrado | F12: Logrado | H12: Logro Incipiente | J12: No logrado
B13: =RUBRICA!A5 -> 1. Describe brevemente en qué consiste el Proyecto APT, justificando su relevancia para el campo laboral de su carrera. | C13: Completamente logrado | D13: =IF($C13=CL,"X","") -> X | E13: =IF(D13="X",100*0.1,"") -> 10 | F13: =IF($C13=L,"X","") | G13: =IF(F13="X",60*0.1,"") | H13: =IF($C13=ML,"X","") | I13: =IF(H13="X",30*0.1,"") | J13: =IF($C13=NL,"X","") | K13: =IF($J13="X",0,"")
B14: =RUBRICA!A6 -> 2. Relaciona el Proyecto APT con las competencias del perfil de egreso de su Plan de Estudio. | C14: Completamente logrado | D14: =IF($C14=CL,"X","") -> X | E14: =IF(D14="X",100*0.05,"") -> 5 | F14: =IF($C14=L,"X","") | G14: =IF(F14="X",60*0.05,"") | H14: =IF($C14=ML,"X","") | I14: =IF(H14="X",30*0.05,"") | J14: =IF($C14=NL,"X","") | K14: =IF($J14="X",0,"")
B15: =RUBRICA!A8 -> 4. Argumenta por qué el proyecto es factible de realizarse en el marco de la asignatura. | C15: Completamente logrado | D15: =IF($C15=CL,"X","") -> X | E15: =IF(D15="X",100*0.05,"") -> 5 | F15: =IF($C15=L,"X","") | G15: =IF(F15="X",60*0.05,"") | H15: =IF($C15=ML,"X","") | I15: =IF(H15="X",30*0.05,"") | J15: =IF($C15=NL,"X","") | K15: =IF($J15="X",0,"")
B16: =RUBRICA!A9 -> 5. Formula objetivos claros, concisos y coherentes con la disciplina y la situación a abordar. | C16: Completamente logrado | D16: =IF($C16=CL,"X","") -> X | E16: =IF(D16="X",100*0.05,"") -> 5 | F16: =IF($C16=L,"X","") | G16: =IF(F16="X",60*0.05,"") | H16: =IF($C16=ML,"X","") | I16: =IF(H16="X",30*0.05,"") | J16: =IF($C16=NL,"X","") | K16: =IF($J16="X",0,"")
B17: =RUBRICA!A10 -> 6. Propone una metodología de trabajo que permite alcanzar los objetivos propuestos y es pertinente con los requerimientos disciplinares. | C17: Completamente logrado | E17: =IF(D17="X",100*0.1,"") | G17: =IF(F17="X",60*0.1,"") | H17: x | I17: =IF(H17="X",30*0.1,"") -> 3 | J17: =IF($C17=NL,"X","") | K17: =IF($J17="X",0,"")
B18: =RUBRICA!A11 -> 7. Establece un plan de trabajo para su proyecto APT considerando los recursos, duración, facilitadores y obstaculizadores en el desarrollo de las actividades. | C18: Completamente logrado | D18: =IF($C18=CL,"X","") -> X | E18: =IF(D18="X",100*0.1,"") -> 10 | F18: =IF($C18=L,"X","") | G18: =IF(F18="X",60*0.1,"") | H18: =IF($C18=ML,"X","") | I18: =IF(H18="X",30*0.1,"") | J18: =IF($C18=NL,"X","") | K18: =IF($J18="X",0,"")
B19: =RUBRICA!A12 -> 8. Determina evidencias, justificando cómo estas dan cuenta del logro de las actividades del Proyecto APT. | C19: Completamente logrado | D19: =IF($C19=CL,"X","") -> X | E19: =IF(D19="X",100*0.05,"") -> 5 | F19: =IF($C19=L,"X","") | G19: =IF(F19="X",60*0.05,"") | H19: =IF($C19=ML,"X","") | I19: =IF(H19="X",30*0.05,"") | J19: =IF($C19=NL,"X","") | K19: =IF($J19="X",0,"")
B20: =RUBRICA!A13 -> 9. Utiliza reglas de redacción, ortografía (literal, puntual, acentual) y las normas para citas y referencias. | C20: Completamente logrado | D20: =IF($C20=CL,"X","") -> X | E20: =IF(D20="X",100*0.05,"") -> 5 | F20: =IF($C20=L,"X","") | G20: =IF(F20="X",60*0.05,"") | H20: =IF($C20=ML,"X","") | I20: =IF(H20="X",30*0.05,"") | J20: =IF($C20=NL,"X","") | K20: =IF($J20="X",0,"")
B21: =RUBRICA!A14 -> 10. Cumple completando el contenido del informe de presentación del proyecto de acuerdo con la plantilla entregada. | C21: Completamente logrado | D21: =IF($C21=CL,"X","") -> X | E21: =IF(D21="X",100*0.05,"") -> 5 | F21: =IF($C21=L,"X","") | G21: =IF(F21="X",60*0.05,"") | H21: =IF($C21=ML,"X","") | I21: =IF(H21="X",30*0.05,"") | J21: =IF($C21=NL,"X","") | K21: =IF($J21="X",0,"")
B22: =RUBRICA!A16 -> 12. Desarrolla un plan de trabajo que permita del logro de los objetivos propuestos del proyecto de acuerdo a los tiempos para su desarrollo | C22: Completamente logrado | D22: =IF($C22=CL,"X","") -> X | E22: =IF(D22="X",100*0.1,"") -> 10 | F22: =IF($C22=L,"X","") | G22: =IF(F22="X",60*0.1,"") | H22: =IF($C22=ML,"X","") | I22: =IF(H22="X",30*0.1,"") | J22: =IF($C22=NL,"X","") | K22: =IF($J22="X",0,"")
B23: Puntaje | C23: =E23+G23+I23+K23 -> 63 | E23: =SUM(E13:E22) -> 60 | G23: =SUM(G13:G22) -> 0 | I23: =SUM(I13:I22) -> 3 | K23: =SUM(K13:K22) -> 0
B24: Nota | C24: =VLOOKUP(C23,ESCALA_IEP!A2:B142,2,FALSE) -> 6.3
A27: INDIVIDUAL | B27: NOMBRE ALUMNO | C27: =$B$4 -> Carlos Manzo
B29: Capacidad de Trabajo en Equipo | C29: Nivel de Logro | D29: NIVELES DE LOGRO Y PUNTAJES
B30: Aspectos a Evaluar | D30: Completamente logrado | F30: Logrado | H30: Medianamente logrado | J30: No logrado
B31: =RUBRICA!A7 -> 3. Relaciona el Proyecto APT con sus intereses profesionales. * | C31: Completamente logrado | D31: =IF($C31=CL,"X","") -> X | E31: =IF(D31="X",100*0.1,"") -> 10 | F31: =IF($C31=L,"X","") | G31: =IF(F31="X",60*0.1,"") | H31: =IF($C31=ML,"X","") | I31: =IF(H31="X",30*0.1,"") | J31: =IF($C31=NL,"X","") | K31: =IF($J31="X",0,"")
B32: =RUBRICA!A15 -> 11. Expone el tema utilizando un lenguaje técnico disciplinar al presentar la propuesta y responde evidenciando un manejo de la información. * | C32: Completamente logrado | D32: =IF($C32=CL,"X","") -> X | E32: =IF(D32="X",100*0.1,"") -> 10 | F32: =IF($C32=L,"X","") | G32: =IF(F32="X",60*0.1,"") | H32: =IF($C32=ML,"X","") | I32: =IF(H32="X",30*0.1,"") | J32: =IF($C32=NL,"X","") | K32: =IF($J32="X",0,"")
B33: =RUBRICA!A17 -> 13. Colaboración y trabajo en equipo * | C33: Completamente logrado | E33: =IF(D33="X",100*0.1,"") | F33: =IF($C33=L,"X","") | G33: =IF(F33="X",60*0.1,"") | H33: x | I33: =IF(H33="X",30*0.1,"") -> 3 | J33: =IF($C33=NL,"X","") | K33: =IF($J33="X",0,"")
B34: PUNTAJE | C34: =E34+G34+I34+K34 -> 23 | E34: =SUM(E31:E33) -> 20 | G34: =SUM(G31:G33) -> 0 | I34: =SUM(I31:I33) -> 3 | K34: =SUM(K31:K33) -> 0
B35: Nota | C35: =VLOOKUP(C34,ESCALA_TRAB_EQUIP!A2:B62,2,FALSE) -> 5.3
A39: INDIVIDUAL | B39: NOMBRE ALUMNO | C39: =B5 -> Benjamin Huentemilla
B41: Capacidad de Trabajo en Equipo | C41: Nivel de Logro | D41: NIVELES DE LOGRO Y PUNTAJES
B42: Aspectos a Evaluar | D42: Completamente logrado | F42: Logrado | H42: Medianamente logrado | J42: No logrado
B43: =RUBRICA!A7 -> 3. Relaciona el Proyecto APT con sus intereses profesionales. * | C43: Completamente logrado | D43: =IF($C43=CL,"X","") -> X | E43: =IF(D43="X",100*0.1,"") -> 10 | F43: =IF($C43=L,"X","") | G43: =IF(F43="X",60*0.1,"") | H43: =IF($C43=ML,"X","") | I43: =IF(H43="X",30*0.1,"") | J43: =IF($C43=NL,"X","") | K43: =IF($J43="X",0,"")
B44: =RUBRICA!A15 -> 11. Expone el tema utilizando un lenguaje técnico disciplinar al presentar la propuesta y responde evidenciando un manejo de la información. * | C44: Completamente logrado | D44: =IF($C44=CL,"X","") -> X | E44: =IF(D44="X",100*0.1,"") -> 10 | F44: =IF($C44=L,"X","") | G44: =IF(F44="X",60*0.1,"") | H44: =IF($C44=ML,"X","") | I44: =IF(H44="X",30*0.1,"") | J44: =IF($C44=NL,"X","") | K44: =IF($J44="X",0,"")
B45: =RUBRICA!A17 -> 13. Colaboración y trabajo en equipo * | C45: Completamente logrado | E45: =IF(D45="X",100*0.1,"") | F45: =IF($C45=L,"X","") | G45: =IF(F45="X",60*0.1,"") | H45: x | I45: =IF(H45="X",30*0.1,"") -> 3 | J45: =IF($C45=NL,"X","") | K45: =IF($J45="X",0,"")
B46: PUNTAJE | C46: =E46+G46+I46+K46 -> 23 | E46: =SUM(E43:E45) -> 20 | G46: =SUM(G43:G45) -> 0 | I46: =SUM(I43:I45) -> 3 | K46: =SUM(K43:K45) -> 0
B47: Nota | C47: =VLOOKUP(C46,ESCALA_TRAB_EQUIP!A2:B62,2,FALSE) -> 5.3
A50: INDIVIDUAL | B50: NOMBRE ALUMNO | C50: =B6 -> Zuar Sepulveda
B52: Capacidad de Trabajo en Equipo | C52: Nivel de Logro | D52: NIVELES DE LOGRO Y PUNTAJES
B53: Aspectos a Evaluar | D53: Completamente logrado | F53: Logrado | H53: Medianamente logrado | J53: No logrado
B54: =RUBRICA!A7 -> 3. Relaciona el Proyecto APT con sus intereses profesionales. * | C54: Completamente logrado | D54: =IF($C54=CL,"X","") -> X | E54: =IF(D54="X",100*0.1,"") -> 10 | F54: =IF($C54=L,"X","") | G54: =IF(F54="X",60*0.1,"") | H54: =IF($C54=ML,"X","") | I54: =IF(H54="X",30*0.1,"") | J54: =IF($C54=NL,"X","") | K54: =IF($J54="X",0,"")
B55: =RUBRICA!A15 -> 11. Expone el tema utilizando un lenguaje técnico disciplinar al presentar la propuesta y responde evidenciando un manejo de la información. * | C55: Completamente logrado | D55: =IF($C55=CL,"X","") -> X | E55: =IF(D55="X",100*0.1,"") -> 10 | F55: =IF($C55=L,"X","") | G55: =IF(F55="X",60*0.1,"") | H55: =IF($C55=ML,"X","") | I55: =IF(H55="X",30*0.1,"") | J55: =IF($C55=NL,"X","") | K55: =IF($J55="X",0,"")
...

Sheet RUBRICA
A2: Indicador de Evaluación | B2: Categorías de Respuesta | F2: Ponderación del Indicador de Evaluación
B3: Completamente Logrado (100%) | C3: Logrado (60%) | D3: Logro incipiente | E3: No logrado
D4: -0.3 | E4: 0
A5: 1. Describe brevemente en qué consiste el Proyecto APT, justificando su relevancia para el campo laboral de su carrera. | B5: Describe brevemente en qué consiste el proyecto APT, justificando la relevancia, impacto o beneficio (real o simulado) que tendría en el campo laboral de su carrera. | C5: Describe brevemente en qué consiste el proyecto APT, señalando la relevancia, impacto o beneficio (real o simulado) que tendría, pero no queda clara la relación con el campo laboral de su carrera. | D5: Describe brevemente en qué consiste el proyecto APT, pero no fue justificado ni relacionado con el campo laboral de su carrera. | E5: No describe o es confuso el proyecto APT, sin justificar ni relacionarlo con el campo laboral de su carrera. | F5: 10
A6: 2. Relaciona el Proyecto APT con las competencias del perfil de egreso de su Plan de Estudio. | B6: Describe una relación coherente entre el proyecto y el perfil de egreso del plan de estudio, especificando cómo debe utilizar distintas competencias para desarrollar su Proyecto APT. | C6: Describe una relación coherente entre el proyecto y el perfil de egreso del plan de estudio, pero no especifica cómo debe utilizar distintas competencias para desarrollar su Proyecto APT. | D6: Describe una relación que tiene elementos pero que no son coherentes entre el proyecto y el perfil de egreso del plan de estudio. | E6: Describe una relación sin coherencia entre el proyecto y el perfil de egreso del plan de estudio o no relaciona el proyecto con el perfil de egreso. | F6: 5
A7: 3. Relaciona el Proyecto APT con sus intereses profesionales. * | B7: Menciona los intereses profesionales y explica con claridad cómo estos se ven reflejados en el proyecto. | C7: Menciona los intereses profesionales, pero no queda completamente clara su conexión con el proyecto. | D7: Menciona los intereses profesionales sin conectarlos con el proyecto. | E7: No menciona los intereses profesionales. | F7: 10
A8: 4. Argumenta por qué el proyecto es factible de realizarse en el marco de la asignatura. | B8: Justifica por qué el proyecto puede desarrollarse considerado tiempo, materiales y factores externos, y en caso de posibles dificultades plantea como las abordaría. | C8: Justifica por qué el proyecto puede desarrollarse, considerando el tiempo y materiales o factores externos y en caso de posibles dificultades no plantea claramente como las abordaría. | D8: Justifica por qué el proyecto puede desarrollarse en el tiempo de la asignatura, sin considerar materiales ni factores externos y en caso de posibles dificultades no plantea como abordarlas. | E8: No justifica las razones de porque el proyecto puede desarrollarse, o el proyecto presentado no es factible de realizarse en el tiempo asignado. | F8: 5
A9: 5. Formula objetivos claros, concisos y coherentes con la disciplina y la situación a abordar. | B9: Formula objetivos claros, concisos y coherentes con la disciplina y la situación a abordar. | C9: Formula objetivos claros y coherentes con la situación a abordar, pero imprecisos de acuerdo a la disciplina. | D9: Formula objetivos confusos, por lo que no queda claro lo que se busca alcanzar ni si es coherente con la situación a abordar. | E9: No plantea objetivos o estos no son coherentes con la disciplina ni la situación a abordar. | F9: 5
A10: 6. Propone una metodología de trabajo que permite alcanzar los objetivos propuestos y es pertinente con los requerimientos disciplinares. | B10: Describe una metodología pertinente con los requerimientos disciplinares, contemplando todos los aspectos necesarios para alcanzar los objetivos planteados. | C10: Describe una metodología pertinente con los requerimientos disciplinares, pero no contempla todos los aspectos necesarios para alcanzar los objetivos planteados. | D10: Describe una metodología que no es del todo pertinente para lograr los objetivos planteados. | E10: No describe una metodología, o bien esta no es pertinente para lograr los objetivos propuestos. | F10: 10
A11: 7. Establece un plan de trabajo para su proyecto APT considerando los recursos, duración, facilitadores y obstaculizadores en el desarrollo de las actividades. | B11: Establece un plan de trabajo con todas las actividades necesarias para cumplir los objetivos, teniendo en consideración los recursos, duración, facilitadores y obstaculizadores. | C11: Establece un plan de trabajo con la mayoría de las actividades necesarias para cumplir los objetivos, teniendo en consideración los recursos, duración, facilitadores y obstaculizadores. | D11: Establece un plan de trabajo que carece de actividades necesarias para cumplir los objetivos y/o no tiene en consideración los recursos, duración, facilitadores y obstaculizadores. | E11: No establece un plan de trabajo, o bien este no permite cumplir los objetivos del proyecto APT. | F11: 10
A12: 8. Determina evidencias, justificando cómo estas dan cuenta del logro de las actividades del Proyecto APT. | B12: Describe evidencias que permiten dar cuenta del logro de las actividades del proyecto APT y justifica su selección. | C12: Describe evidencias que permiten dar cuenta del logro de las actividades del proyecto APT, pero no justifica con claridad su selección. | D12: Describe evidencias que permiten dar cuenta del logro de solo algunas actividades del proyecto APT y/o no justifica su selección. | E12: No incluye evidencias que pueden dar cuenta del desarrollo del proyecto. | F12: 5
A13: 9. Utiliza reglas de redacción, ortografía (literal, puntual, acentual) y las normas para citas y referencias. | B13: El texto cumple con las reglas ortografía y de redacción en todos sus apartados y utiliza correctamente todas las normas de citación y referencias. | C13: El texto presenta de 1 a 5 errores de ortografía, redacción o en las citas y referencias del informe. | D13: El texto presenta de 6 a 10 errores de ortografía, redacción o en las citas y referencias del informe. | E13: El texto presenta más de 10 errores de ortografía, redacción o en las citas y referencias del informe. | F13: 5
A14: 10. Cumple completando el contenido del informe de presentación del proyecto de acuerdo con la plantilla entregada. | B14: Cumple con todos los ítems solicitados en el informe de presentación del proyecto, siendo estos contenidos coherentes con lo solicitado en cada ítem | C14: No cumple con todos los ítems solicitados en el informe de presentación del proyecto, siendo los contenidos entregados coherentes con lo solicitado en cada ítem | D14: No cumple con todos los ítems solicitados en el informe de presentación del proyecto, siendo los contenidos entregados coherentes con lo solicitado en cada ítem | E14: No cumple con todos los ítems solicitados en el informe de presentación del proyecto, y los contenidos entregados son poco coherentes con lo solicitado en cada ítem | F14: 5
A15: 11. Expone el tema utilizando un lenguaje técnico disciplinar al presentar la propuesta y responde evidenciando un manejo de la información. * | B15: Expone el tema utilizando un lenguaje técnico disciplinar al presentar la propuesta y responde evidenciando un manejo de la información en todo momento | C15: Expone el tema utilizando un lenguaje técnico disciplinar al presentar la propuesta y responde evidenciando un manejo de la información la mayoría del tiempo. | D15: Expone el tema utilizando un lenguaje técnico disciplinar al presentar la propuesta y responde evidenciando un manejo de la información la mitad del tiempo. | E15: Expone el tema utilizando un lenguaje técnico disciplinar al presentar la propuesta y responde evidenciando un manejo de la información en menos de la mitad del tiempo. | F15: 10
A16: 12. Desarrolla un plan de trabajo que permita del logro de los objetivos propuestos del proyecto de acuerdo a los tiempos para su desarrollo | B16: Desarrolla un plan de trabajo que permite el logro de los objetivos propuestos del proyecto de acuerdo a los tiempos para su desarrollo y contiene hitos claros para demostrar el estado de avance | C16: Desarrolla un plan de trabajo que permita el logro de los objetivos propuestos del proyecto de acuerdo a los tiempos para su desarrollo pero no demuestran hitos claros para demostrar el estado de avance | D16: El desarrollo del plan de trabajo no permite determinar si el logro de los objetivos propuestos del proyecto son alcanzables en los tiempos para su desarrollo pero si demuestran hitos claros para demostrar el estado de avance | E16: El desarrollo del plan de trabajo no permite determinar si el logro de los objetivos propuestos del proyecto son alcanzables en los tiempos para su desarrollo y no demuestran hitos claros para demostrar el estado de avance | F16: 10
A17: 13. Colaboración y trabajo en equipo * | B17: El estudiante realiza un excelente trabajo en equipo, fomentando un ambiente positivo, siendo participativo con su equipo en las sesiones presenciales de la asignatura y participando de manera equitativa en la presentación del caso | C17: El estudiante realiza un buen trabajo en equipo, fomentando un ambiente positivo, siendo participativo con su equipo en las sesiones presenciales de la asignatura, pero no demuestra una participación de manera equitativa en la presentación del caso | D17: El estudiante realiza un trabajo deficiente con el equipo, fomentando un ambiente positivo pero no demuestra ser participativo con su equipo en las sesiones presenciales de la asignatura o se ausenta constantemente y/o no demuestra una participación de manera equitativa en la presentación del caso | E17: El estudiante realiza un mal trabajo con el equipo no fomentando un ambiente positivo, no demuestra ser participativo con su equipo en las sesiones presenciales de la asignatura o se ausenta constantemente y no demuestra una participación de manera equitativa en la presentación del caso | F17: 10
A18: Total | F18: 1

Sheet Hoja1
B2: Análisis del Video Según la Rúbrica
B4: 1. Describe brevemente en qué consiste el Proyecto APT, justificando su relevancia para el campo laboral de su carrera.
B6: Evaluación: Logrado (100%) - 10 Puntos
B8: Justificación: El video describe de manera clara y detallada el proyecto: el desarrollo de una plataforma web para digitalizar y automatizar la gestión de partidas de rol [01:31:00]. La relevancia para el campo laboral es evidente, ya que aplican tecnologías y arquitecturas de software modernas y demandadas como la arquitectura de tres capas, API REST con Django y bases de datos con PostgreSQL [02:51:85], demostrando la aplicación práctica de conocimientos de ingeniería de software.
B10: 2. Relaciona el Proyecto APT con las competencias del perfil de egreso de su Plan de Estudio.
B12: Evaluación: Logrado - 5 Puntos
B14: Justificación: El proyecto demuestra competencias clave de un perfil de egreso en ingeniería o desarrollo de software, como el análisis de requerimientos (historias de usuario [05:27:00]), diseño de arquitectura de software, implementación de soluciones (prototipo funcional [08:02:00]) y gestión de proyectos bajo metodologías ágiles (Scrum [09:12:08]).
B16: 3. Relaciona el Proyecto APT con sus intereses profesionales.
B18: Evaluación: Logrado (100%) - 10 Puntos
B20: Justificación: Se menciona explícitamente el interés por resolver problemas reales como la frustración del jugador [01:20:94] y la carga administrativa del personal [01:25:31]. El enfoque en optimizar la experiencia de usuario y la eficiencia operativa demuestra un claro interés profesional en el desarrollo de software orientado a soluciones de negocio.
B22: 4. Argumenta por qué el proyecto es factible de realizarse en el marco de la asignatura.
B24: Evaluación: Logrado (100%) - 5 Puntos
... B80: Justificación: Aunque la presentación la realiza una sola persona, el uso del plural ("decidimos", "nuestro backlog") y la elección de la metodología Scrum, que se fundamenta en la colaboración, son evidencias claras de un trabajo en equipo bien ejecutado.

Sheet ESCALA_IEP
A1: Puntaje | B1: Nota
A2: 0 | B2: 1
A3: 0.5 | B3: 1
A4: 1 | B4: 1.1
A5: 1.5 | B5: 1.1
A6: 2 | B6: 1.1
A7: 2.5 | B7: 1.2
A8: 3 | B8: 1.2
A9: 3.5 | B9: 1.3
A10: 4 | B10: 1.3
A11: 4.5 | B11: 1.3
A12: 5 | B12: 1.4
A13: 5.5 | B13: 1.4
... A142: 70 | B142: 7

Sheet ESCALA_PRESENTACION
A1: PUNTOS | B1: NOTA
A2: 0 | B2: 1
A3: 1 | B3: 1.1
A4: 2 | B4: 1.2
A5: 3 | B5: 1.3
A6: 4 | B6: 1.4
A7: 5 | B7: 1.5
A8: 6 | B8: 1.6
A9: 7 | B9: 1.7
A10: 8 | B10: 1.8
A11: 9 | B11: 1.9
A12: 10 | B12: 2
A13: 11 | B13: 2.1
... A54: 52 | B54: 7

Sheet ESCALA_TRAB_EQUIP
A1: Puntaje | B1: Nota
A2: 0 | B2: 1
A3: 0.5 | B3: 1.1
A4: 1 | B4: 1.2
A5: 1.5 | B5: 1.3
A6: 2 | B6: 1.3
A7: 2.5 | B7: 1.4
A8: 3 | B8: 1.5
A9: 3.5 | B9: 1.6
A10: 4 | B10: 1.7
A11: 4.5 | B11: 1.8
A12: 5 | B12: 1.8
A13: 5.5 | B13: 1.9
... A62: 30 | B62: 7

Sheet RELEVANCIA-PUNTAJE
A1: Relevancia | B1: Puntaje
B2: Completamente logrado | C2: Logrado | D2: Logro incipiente | E2: No logrado
A3: Muy Relevante | B3: 4 | C3: 3 | D3: 2 | E3: 0
